<?xml version="1.0" ?>
<!-- =================================================================================== -->
<!-- |    This document was autogenerated by xacro from /home/wizard/Documents/Escola/AAU/Master/8_semester/Object_manipulation_and_task_planning/OMTP/src/omtp_lecture_1/omtp_support/urdf/omtp_factory.xacro | -->
<!-- |    EDITING THIS FILE BY HAND IS NOT RECOMMENDED                                 | -->
<!-- =================================================================================== -->
<!-- =================================================================================== -->
<!-- |    This document was autogenerated by xacro from /home/wizard/Documents/Escola/AAU/Master/8_semester/Object_manipulation_and_task_planning/OMTP/src/omtp_lecture_1/omtp_support/urdf/omtp_factory.xacro | -->
<!-- |    EDITING THIS FILE BY HAND IS NOT RECOMMENDED                                 | -->
<!-- =================================================================================== -->
<robot name="omtp">
    <!-- ==================================================== -->
    <!-- INITIAL SETUP OF WORLD LINK AND WORLD_INTERFACE LINK -->
    <!-- ==================================================== -->
    <!-- world -->
    <link name="world" />
    <!-- world_interface. Makes it convenient to move the whole environment according to the world origin -->
    <link name="world_interface" />
    <!-- world<->world_interface joint -->
    <joint name="world_interface_to_world" type="fixed">
        <parent link="world" />
        <child link="world_interface" />
    </joint>
    <!-- Links -->
    <link name="fib14">
        <visual>
            <geometry>
                <mesh filename="package://aau_lab_ros_models/meshes/fib14/fib14.dae" />
            </geometry>
        </visual>
        <collision>
            <geometry>
                <mesh filename="package://aau_lab_ros_models/meshes/fib14/fib14.dae" />
            </geometry>
        </collision>

        <inertial>
            <inertia ixx="1.0" ixy="0" ixz="0" iyy="1.0" iyz="0" izz="1.0" />
            <mass value="100" />
        </inertial>

    </link>
    <joint name="fib14_to_world_interface" type="fixed">
        <parent link="world_interface" />
        <child link="fib14" />
        <origin rpy="0 0 0" xyz="0 0 0" />
    </joint>
    <joint name="panda_1_virtual_joint" type="fixed">
        <parent link="robot1_pedestal_link" />
        <child link="panda_1_link0" />
        <origin rpy="0 0 0" xyz="0 0 0.95" />
    </joint>
    <link name="panda_1_link0">
        <visual>
            <geometry>
                <mesh filename="package://franka_description/meshes/visual/link0.dae" />
            </geometry>
        </visual>
        <collision>
            <origin rpy="0 0 0" xyz="0 0 -0.1915" />
            <geometry>
                <cylinder length="0.2830" radius="0.09" />
            </geometry>
        </collision>
        <collision>
            <origin rpy="0 0 0" xyz="0 0 -0.333" />
            <geometry>
                <sphere radius="0.09" />
            </geometry>
        </collision>
        <collision>
            <origin rpy="0 0 0" xyz="0 0 -0.05" />
            <geometry>
                <sphere radius="0.09" />
            </geometry>
        </collision>

<inertial>
            <mass value="0.1" />
            <inertia ixx="0.03" ixy="0.0" ixz="0.0" iyy="0.03" iyz="0.0" izz="0.03" />
        </inertial>

    </link>
    <link name="panda_1_link1">
        <visual>
            <geometry>
                <mesh filename="package://franka_description/meshes/visual/link1.dae" />
            </geometry>
        </visual>
        <collision>
            <origin rpy="0 0 0" xyz="0 0 -0.1915" />
            <geometry>
                <cylinder length="0.2830" radius="0.09" />
            </geometry>
        </collision>
        <collision>
            <origin rpy="0 0 0" xyz="0 0 -0.333" />
            <geometry>
                <sphere radius="0.09" />
            </geometry>
        </collision>
        <collision>
            <origin rpy="0 0 0" xyz="0 0 -0.05" />
            <geometry>
                <sphere radius="0.09" />
            </geometry>
        </collision>

<inertial>
            <mass value="0.1" />
            <inertia ixx="0.03" ixy="0.0" ixz="0.0" iyy="0.03" iyz="0.0" izz="0.03" />
        </inertial>

    </link>
    <link name="panda_1_link2">
        <visual>
            <geometry>
                <mesh filename="package://franka_description/meshes/visual/link2.dae" />
            </geometry>
        </visual>
        <collision>
            <origin rpy="0 0 0" xyz="0 0 0" />
            <geometry>
                <cylinder length="0.12" radius="0.09" />
            </geometry>
        </collision>
        <collision>
            <origin rpy="0 0 0" xyz="0 0 -0.06" />
            <geometry>
                <sphere radius="0.09" />
            </geometry>
        </collision>
        <collision>
            <origin rpy="0 0 0" xyz="0 0 0.06" />
            <geometry>
                <sphere radius="0.09" />
            </geometry>
        </collision>

<inertial>
            <mass value="0.1" />
            <inertia ixx="0.03" ixy="0.0" ixz="0.0" iyy="0.03" iyz="0.0" izz="0.03" />
        </inertial>

    </link>
    <link name="panda_1_link3">
        <visual>
            <geometry>
                <mesh filename="package://franka_description/meshes/visual/link3.dae" />
            </geometry>
        </visual>
        <collision>
            <origin rpy="0 0 0" xyz="0 0 -0.145" />
            <geometry>
                <cylinder length="0.15" radius="0.09" />
            </geometry>
        </collision>
        <collision>
            <origin rpy="0 0 0" xyz="0 0 -0.22" />
            <geometry>
                <sphere radius="0.09" />
            </geometry>
        </collision>
        <collision>
            <origin rpy="0 0 0" xyz="0 0 -0.07" />
            <geometry>
                <sphere radius="0.09" />
            </geometry>
        </collision>

<inertial>
            <mass value="0.1" />
            <inertia ixx="0.03" ixy="0.0" ixz="0.0" iyy="0.03" iyz="0.0" izz="0.03" />
        </inertial>

    </link>
    <link name="panda_1_link4">
        <visual>
            <geometry>
                <mesh filename="package://franka_description/meshes/visual/link4.dae" />
            </geometry>
        </visual>
        <collision>
            <origin rpy="0 0 0" xyz="0 0 0" />
            <geometry>
                <cylinder length="0.12" radius="0.09" />
            </geometry>
        </collision>
        <collision>
            <origin rpy="0 0 0" xyz="0 0 0.06" />
            <geometry>
                <sphere radius="0.09" />
            </geometry>
        </collision>
        <collision>
            <origin rpy="0 0 0" xyz="0 0 -0.06" />
            <geometry>
                <sphere radius="0.09" />
            </geometry>
        </collision>

<inertial>
            <mass value="0.1" />
            <inertia ixx="0.03" ixy="0.0" ixz="0.0" iyy="0.03" iyz="0.0" izz="0.03" />
        </inertial>

    </link>
    <link name="panda_1_link5">
        <visual>
            <geometry>
                <mesh filename="package://franka_description/meshes/visual/link5.dae" />
            </geometry>
        </visual>
        <collision>
            <origin rpy="0 0 0" xyz="0 0 -0.26" />
            <geometry>
                <cylinder length="0.1" radius="0.09" />
            </geometry>
        </collision>
        <collision>
            <origin rpy="0 0 0" xyz="0 0 -0.31" />
            <geometry>
                <sphere radius="0.09" />
            </geometry>
        </collision>
        <collision>
            <origin rpy="0 0 0" xyz="0 0 -0.21" />
            <geometry>
                <sphere radius="0.09" />
            </geometry>
        </collision>
        <collision>
            <origin rpy="0 0 0" xyz="0 0.08 -0.13" />
            <geometry>
                <cylinder length="0.14" radius="0.055" />
            </geometry>
        </collision>
        <collision>
            <origin rpy="0 0 0" xyz="0 0.08 -0.06" />
            <geometry>
                <sphere radius="0.055" />
            </geometry>
        </collision>
        <collision>
            <origin rpy="0 0 0" xyz="0 0.08 -0.20" />
            <geometry>
                <sphere radius="0.055" />
            </geometry>
        </collision>

<inertial>
            <mass value="0.1" />
            <inertia ixx="0.03" ixy="0.0" ixz="0.0" iyy="0.03" iyz="0.0" izz="0.03" />
        </inertial>

    </link>
    <link name="panda_1_link6">
        <visual>
            <geometry>
                <mesh filename="package://franka_description/meshes/visual/link6.dae" />
            </geometry>
        </visual>
        <collision>
            <origin rpy="0 0 0" xyz="0 0 -0.03" />
            <geometry>
                <cylinder length="0.08" radius="0.08" />
            </geometry>
        </collision>
        <collision>
            <origin rpy="0 0 0" xyz="0 0 0.01" />
            <geometry>
                <sphere radius="0.08" />
            </geometry>
        </collision>
        <collision>
            <origin rpy="0 0 0" xyz="0 0 -0.07" />
            <geometry>
                <sphere radius="0.08" />
            </geometry>
        </collision>

<inertial>
            <mass value="0.1" />
            <inertia ixx="0.03" ixy="0.0" ixz="0.0" iyy="0.03" iyz="0.0" izz="0.03" />
        </inertial>

    </link>
    <link name="panda_1_link7">
        <visual>
            <geometry>
                <mesh filename="package://franka_description/meshes/visual/link7.dae" />
            </geometry>
        </visual>
        <collision>
            <origin rpy="0 0 0" xyz="0 0 0.01" />
            <geometry>
                <cylinder length="0.14" radius="0.07" />
            </geometry>
        </collision>
        <collision>
            <origin rpy="0 0 0" xyz="0 0 0.08" />
            <geometry>
                <sphere radius="0.07" />
            </geometry>
        </collision>
        <collision>
            <origin rpy="0 0 0" xyz="0 0 -0.06" />
            <geometry>
                <sphere radius="0.07" />
            </geometry>
        </collision>

<inertial>
            <mass value="0.1" />
            <inertia ixx="0.03" ixy="0.0" ixz="0.0" iyy="0.03" iyz="0.0" izz="0.03" />
        </inertial>

    </link>
    <link name="panda_1_link8">
        <collision>
            <origin rpy="3.141592653589793 1.5707963267948966 1.5707963267948966" xyz="0.0424 0.0424 -0.0250" />
            <geometry>
                <cylinder length="0.01" radius="0.06" />
            </geometry>
        </collision>
        <collision>
            <origin rpy="0 0 0" xyz="0.0424 0.0424 -0.02" />
            <geometry>
                <sphere radius="0.06" />
            </geometry>
        </collision>
        <collision>
            <origin rpy="0 0 0" xyz="0.0424 0.0424 -0.03" />
            <geometry>
                <sphere radius="0.06" />
            </geometry>
        </collision>

<inertial>
            <mass value="0.1" />
            <inertia ixx="0.03" ixy="0.0" ixz="0.0" iyy="0.03" iyz="0.0" izz="0.03" />
        </inertial>

    </link>
    <joint name="panda_1_joint1" type="revolute">
        <safety_controller k_position="100.0" k_velocity="40.0" soft_lower_limit="-2.8973" soft_upper_limit="2.8973" />
        <origin rpy="0 0 0" xyz="0 0 0.333" />
        <parent link="panda_1_link0" />
        <child link="panda_1_link1" />
        <limit effort="87" lower="-2.8973" upper="2.8973" velocity="2.175" />
        <axis xyz="0 0 1" />
        <dynamics damping="1.0" />
    </joint>
    <joint name="panda_1_joint2" type="revolute">
        <safety_controller k_position="100.0" k_velocity="40.0" soft_lower_limit="-1.7628" soft_upper_limit="1.7628" />
        <origin rpy="-1.5707963267948966 0 0" xyz="0 0 0" />
        <parent link="panda_1_link1" />
        <child link="panda_1_link2" />
        <limit effort="87" lower="-1.7628" upper="1.7628" velocity="2.175" />
        <axis xyz="0 0 1" />
        <dynamics damping="1.0" />
    </joint>
    <joint name="panda_1_joint3" type="revolute">
        <safety_controller k_position="100.0" k_velocity="40.0" soft_lower_limit="-2.8973" soft_upper_limit="2.8973" />
        <origin rpy="1.5707963267948966 0 0" xyz="0 -0.316 0" />
        <parent link="panda_1_link2" />
        <child link="panda_1_link3" />
        <limit effort="87" lower="-2.8973" upper="2.8973" velocity="2.175" />
        <axis xyz="0 0 1" />
        <dynamics damping="1.0" />
    </joint>
    <joint name="panda_1_joint4" type="revolute">
        <safety_controller k_position="100.0" k_velocity="40.0" soft_lower_limit="-3.0718" soft_upper_limit="-0.0698" />
        <origin rpy="1.5707963267948966 0 0" xyz="0.0825 0 0" />
        <parent link="panda_1_link3" />
        <child link="panda_1_link4" />
        <limit effort="87" lower="-3.0718" upper="-0.0698" velocity="2.175" />
        <axis xyz="0 0 1" />
        <dynamics damping="1.0" />
    </joint>
    <joint name="panda_1_joint5" type="revolute">
        <safety_controller k_position="100.0" k_velocity="40.0" soft_lower_limit="-2.8973" soft_upper_limit="2.8973" />
        <origin rpy="-1.5707963267948966 0 0" xyz="-0.0825 0.384 0" />
        <parent link="panda_1_link4" />
        <child link="panda_1_link5" />
        <limit effort="12" lower="-2.8973" upper="2.8973" velocity="2.61" />
        <axis xyz="0 0 1" />
        <dynamics damping="1.0" />
    </joint>
    <joint name="panda_1_joint6" type="revolute">
        <safety_controller k_position="100.0" k_velocity="40.0" soft_lower_limit="-0.0175" soft_upper_limit="3.7525" />
        <origin rpy="1.5707963267948966 0 0" xyz="0 0 0" />
        <parent link="panda_1_link5" />
        <child link="panda_1_link6" />
        <limit effort="12" lower="-0.0175" upper="3.7525" velocity="2.61" />
        <axis xyz="0 0 1" />
        <dynamics damping="1.0" />
    </joint>
    <joint name="panda_1_joint7" type="revolute">
        <safety_controller k_position="100.0" k_velocity="40.0" soft_lower_limit="-2.8973" soft_upper_limit="2.8973" />
        <origin rpy="1.5707963267948966 0 0" xyz="0.088 0 0" />
        <parent link="panda_1_link6" />
        <child link="panda_1_link7" />
        <limit effort="12" lower="-2.8973" upper="2.8973" velocity="2.61" />
        <axis xyz="0 0 1" />
        <dynamics damping="1.0" />
    </joint>
    <joint name="panda_1_joint8" type="fixed">
        <origin rpy="0 0 0" xyz="0 0 0.107" />
        <parent link="panda_1_link7" />
        <child link="panda_1_link8" />
        <axis xyz="0 0 0" />
        <dynamics damping="1.0" />
    </joint>
    <joint name="panda_1_hand_joint" type="fixed">
        <parent link="panda_1_link8" />
        <child link="panda_1_hand" />
        <origin rpy="0 0 -0.7853981633974483" xyz="0 0 0" />
    </joint>
    <link name="panda_1_hand">
        <visual>
            <geometry>
                <mesh filename="package://franka_description/meshes/visual/hand.dae" />
            </geometry>
        </visual>
        <collision>
            <origin rpy="0 1.5707963267948966 1.5707963267948966" xyz="0 0 0.04" />
            <geometry>
                <cylinder length="0.1" radius="0.07" />
            </geometry>
        </collision>
        <collision>
            <origin rpy="0 0 0" xyz="0 -0.05 0.04" />
            <geometry>
                <sphere radius="0.07" />
            </geometry>
        </collision>
        <collision>
            <origin rpy="0 0 0" xyz="0 0.05 0.04" />
            <geometry>
                <sphere radius="0.07" />
            </geometry>
        </collision>
        <collision>
            <origin rpy="0 1.5707963267948966 1.5707963267948966" xyz="0 0 0.1" />
            <geometry>
                <cylinder length="0.1" radius="0.05" />
            </geometry>
        </collision>
        <collision>
            <origin rpy="0 0 0" xyz="0 -0.05 0.1" />
            <geometry>
                <sphere radius="0.05" />
            </geometry>
        </collision>
        <collision>
            <origin rpy="0 0 0" xyz="0 0.05 0.1" />
            <geometry>
                <sphere radius="0.05" />
            </geometry>
        </collision>

<inertial>
            <mass value="0.1" />
            <inertia ixx="0.03" ixy="0.0" ixz="0.0" iyy="0.03" iyz="0.0" izz="0.03" />
        </inertial>

    </link>
    <link name="panda_1_leftfinger">
        <visual>
            <geometry>
                <mesh filename="package://franka_description/meshes/visual/finger.dae" />
            </geometry>
        </visual>
        <collision>
            <geometry>
                <sphere radius="0.05" />
            </geometry>
        </collision>

<inertial>
            <mass value="0.1" />
            <inertia ixx="0.03" ixy="0.0" ixz="0.0" iyy="0.03" iyz="0.0" izz="0.03" />
        </inertial>

    </link>
    <link name="panda_1_rightfinger">
        <visual>
            <origin rpy="0 0 3.141592653589793" xyz="0 0 0" />
            <geometry>
                <mesh filename="package://franka_description/meshes/visual/finger.dae" />
            </geometry>
        </visual>
        <collision>
            <geometry>
                <sphere radius="0.05" />
            </geometry>
        </collision>

<inertial>
            <mass value="0.1" />
            <inertia ixx="0.03" ixy="0.0" ixz="0.0" iyy="0.03" iyz="0.0" izz="0.03" />
        </inertial>

    </link>
    <joint name="panda_1_finger_joint1" type="prismatic">
        <parent link="panda_1_hand" />
        <child link="panda_1_leftfinger" />
        <origin rpy="0 0 0" xyz="0 0 0.0584" />
        <axis xyz="0 1 0" />
        <limit effort="150" lower="0.0" upper="0.04" velocity="0.2" />
    </joint>
    <joint name="panda_1_finger_joint2" type="prismatic">
        <parent link="panda_1_hand" />
        <child link="panda_1_rightfinger" />
        <origin rpy="0 0 0" xyz="0 0 0.0584" />
        <axis xyz="0 -1 0" />
        <limit effort="150" lower="0.0" upper="0.04" velocity="0.2" />
        <mimic joint="panda_1_finger_joint1" />
    </joint>
    <joint name="panda_2_virtual_joint" type="fixed">
        <parent link="robot2_pedestal_link" />
        <child link="panda_2_link0" />
        <origin rpy="0 0 0" xyz="0 0 0.95" />
    </joint>
    <link name="panda_2_link0">
        <visual>
            <geometry>
                <mesh filename="package://franka_description/meshes/visual/link0.dae" />
            </geometry>
        </visual>
        <collision>
            <origin rpy="0 0 0" xyz="0 0 -0.1915" />
            <geometry>
                <cylinder length="0.2830" radius="0.09" />
            </geometry>
        </collision>
        <collision>
            <origin rpy="0 0 0" xyz="0 0 -0.333" />
            <geometry>
                <sphere radius="0.09" />
            </geometry>
        </collision>
        <collision>
            <origin rpy="0 0 0" xyz="0 0 -0.05" />
            <geometry>
                <sphere radius="0.09" />
            </geometry>
        </collision>

<inertial>
            <mass value="0.1" />
            <inertia ixx="0.03" ixy="0.0" ixz="0.0" iyy="0.03" iyz="0.0" izz="0.03" />
        </inertial>

    </link>
    <link name="panda_2_link1">
        <visual>
            <geometry>
                <mesh filename="package://franka_description/meshes/visual/link1.dae" />
            </geometry>
        </visual>
        <collision>
            <origin rpy="0 0 0" xyz="0 0 -0.1915" />
            <geometry>
                <cylinder length="0.2830" radius="0.09" />
            </geometry>
        </collision>
        <collision>
            <origin rpy="0 0 0" xyz="0 0 -0.333" />
            <geometry>
                <sphere radius="0.09" />
            </geometry>
        </collision>
        <collision>
            <origin rpy="0 0 0" xyz="0 0 -0.05" />
            <geometry>
                <sphere radius="0.09" />
            </geometry>
        </collision>

<inertial>
            <mass value="0.1" />
            <inertia ixx="0.03" ixy="0.0" ixz="0.0" iyy="0.03" iyz="0.0" izz="0.03" />
        </inertial>

    </link>
    <link name="panda_2_link2">
        <visual>
            <geometry>
                <mesh filename="package://franka_description/meshes/visual/link2.dae" />
            </geometry>
        </visual>
        <collision>
            <origin rpy="0 0 0" xyz="0 0 0" />
            <geometry>
                <cylinder length="0.12" radius="0.09" />
            </geometry>
        </collision>
        <collision>
            <origin rpy="0 0 0" xyz="0 0 -0.06" />
            <geometry>
                <sphere radius="0.09" />
            </geometry>
        </collision>
        <collision>
            <origin rpy="0 0 0" xyz="0 0 0.06" />
            <geometry>
                <sphere radius="0.09" />
            </geometry>
        </collision>

<inertial>
            <mass value="0.1" />
            <inertia ixx="0.03" ixy="0.0" ixz="0.0" iyy="0.03" iyz="0.0" izz="0.03" />
        </inertial>

    </link>
    <link name="panda_2_link3">
        <visual>
            <geometry>
                <mesh filename="package://franka_description/meshes/visual/link3.dae" />
            </geometry>
        </visual>
        <collision>
            <origin rpy="0 0 0" xyz="0 0 -0.145" />
            <geometry>
                <cylinder length="0.15" radius="0.09" />
            </geometry>
        </collision>
        <collision>
            <origin rpy="0 0 0" xyz="0 0 -0.22" />
            <geometry>
                <sphere radius="0.09" />
            </geometry>
        </collision>
        <collision>
            <origin rpy="0 0 0" xyz="0 0 -0.07" />
            <geometry>
                <sphere radius="0.09" />
            </geometry>
        </collision>

<inertial>
            <mass value="0.1" />
            <inertia ixx="0.03" ixy="0.0" ixz="0.0" iyy="0.03" iyz="0.0" izz="0.03" />
        </inertial>

    </link>
    <link name="panda_2_link4">
        <visual>
            <geometry>
                <mesh filename="package://franka_description/meshes/visual/link4.dae" />
            </geometry>
        </visual>
        <collision>
            <origin rpy="0 0 0" xyz="0 0 0" />
            <geometry>
                <cylinder length="0.12" radius="0.09" />
            </geometry>
        </collision>
        <collision>
            <origin rpy="0 0 0" xyz="0 0 0.06" />
            <geometry>
                <sphere radius="0.09" />
            </geometry>
        </collision>
        <collision>
            <origin rpy="0 0 0" xyz="0 0 -0.06" />
            <geometry>
                <sphere radius="0.09" />
            </geometry>
        </collision>

<inertial>
            <mass value="0.1" />
            <inertia ixx="0.03" ixy="0.0" ixz="0.0" iyy="0.03" iyz="0.0" izz="0.03" />
        </inertial>

    </link>
    <link name="panda_2_link5">
        <visual>
            <geometry>
                <mesh filename="package://franka_description/meshes/visual/link5.dae" />
            </geometry>
        </visual>
        <collision>
            <origin rpy="0 0 0" xyz="0 0 -0.26" />
            <geometry>
                <cylinder length="0.1" radius="0.09" />
            </geometry>
        </collision>
        <collision>
            <origin rpy="0 0 0" xyz="0 0 -0.31" />
            <geometry>
                <sphere radius="0.09" />
            </geometry>
        </collision>
        <collision>
            <origin rpy="0 0 0" xyz="0 0 -0.21" />
            <geometry>
                <sphere radius="0.09" />
            </geometry>
        </collision>
        <collision>
            <origin rpy="0 0 0" xyz="0 0.08 -0.13" />
            <geometry>
                <cylinder length="0.14" radius="0.055" />
            </geometry>
        </collision>
        <collision>
            <origin rpy="0 0 0" xyz="0 0.08 -0.06" />
            <geometry>
                <sphere radius="0.055" />
            </geometry>
        </collision>
        <collision>
            <origin rpy="0 0 0" xyz="0 0.08 -0.20" />
            <geometry>
                <sphere radius="0.055" />
            </geometry>
        </collision>

<inertial>
            <mass value="0.1" />
            <inertia ixx="0.03" ixy="0.0" ixz="0.0" iyy="0.03" iyz="0.0" izz="0.03" />
        </inertial>

    </link>
    <link name="panda_2_link6">
        <visual>
            <geometry>
                <mesh filename="package://franka_description/meshes/visual/link6.dae" />
            </geometry>
        </visual>
        <collision>
            <origin rpy="0 0 0" xyz="0 0 -0.03" />
            <geometry>
                <cylinder length="0.08" radius="0.08" />
            </geometry>
        </collision>
        <collision>
            <origin rpy="0 0 0" xyz="0 0 0.01" />
            <geometry>
                <sphere radius="0.08" />
            </geometry>
        </collision>
        <collision>
            <origin rpy="0 0 0" xyz="0 0 -0.07" />
            <geometry>
                <sphere radius="0.08" />
            </geometry>
        </collision>

<inertial>
            <mass value="0.1" />
            <inertia ixx="0.03" ixy="0.0" ixz="0.0" iyy="0.03" iyz="0.0" izz="0.03" />
        </inertial>

    </link>
    <link name="panda_2_link7">
        <visual>
            <geometry>
                <mesh filename="package://franka_description/meshes/visual/link7.dae" />
            </geometry>
        </visual>
        <collision>
            <origin rpy="0 0 0" xyz="0 0 0.01" />
            <geometry>
                <cylinder length="0.14" radius="0.07" />
            </geometry>
        </collision>
        <collision>
            <origin rpy="0 0 0" xyz="0 0 0.08" />
            <geometry>
                <sphere radius="0.07" />
            </geometry>
        </collision>
        <collision>
            <origin rpy="0 0 0" xyz="0 0 -0.06" />
            <geometry>
                <sphere radius="0.07" />
            </geometry>
        </collision>

<inertial>
            <mass value="0.1" />
            <inertia ixx="0.03" ixy="0.0" ixz="0.0" iyy="0.03" iyz="0.0" izz="0.03" />
        </inertial>

    </link>
    <link name="panda_2_link8">
        <collision>
            <origin rpy="3.141592653589793 1.5707963267948966 1.5707963267948966" xyz="0.0424 0.0424 -0.0250" />
            <geometry>
                <cylinder length="0.01" radius="0.06" />
            </geometry>
        </collision>
        <collision>
            <origin rpy="0 0 0" xyz="0.0424 0.0424 -0.02" />
            <geometry>
                <sphere radius="0.06" />
            </geometry>
        </collision>
        <collision>
            <origin rpy="0 0 0" xyz="0.0424 0.0424 -0.03" />
            <geometry>
                <sphere radius="0.06" />
            </geometry>
        </collision>

<inertial>
            <mass value="0.1" />
            <inertia ixx="0.03" ixy="0.0" ixz="0.0" iyy="0.03" iyz="0.0" izz="0.03" />
        </inertial>

    </link>
    <joint name="panda_2_joint1" type="revolute">
        <safety_controller k_position="100.0" k_velocity="40.0" soft_lower_limit="-2.8973" soft_upper_limit="2.8973" />
        <origin rpy="0 0 0" xyz="0 0 0.333" />
        <parent link="panda_2_link0" />
        <child link="panda_2_link1" />
        <limit effort="87" lower="-2.8973" upper="2.8973" velocity="2.175" />
        <axis xyz="0 0 1" />
        <dynamics damping="1.0" />
    </joint>
    <joint name="panda_2_joint2" type="revolute">
        <safety_controller k_position="100.0" k_velocity="40.0" soft_lower_limit="-1.7628" soft_upper_limit="1.7628" />
        <origin rpy="-1.5707963267948966 0 0" xyz="0 0 0" />
        <parent link="panda_2_link1" />
        <child link="panda_2_link2" />
        <limit effort="87" lower="-1.7628" upper="1.7628" velocity="2.175" />
        <axis xyz="0 0 1" />
        <dynamics damping="1.0" />
    </joint>
    <joint name="panda_2_joint3" type="revolute">
        <safety_controller k_position="100.0" k_velocity="40.0" soft_lower_limit="-2.8973" soft_upper_limit="2.8973" />
        <origin rpy="1.5707963267948966 0 0" xyz="0 -0.316 0" />
        <parent link="panda_2_link2" />
        <child link="panda_2_link3" />
        <limit effort="87" lower="-2.8973" upper="2.8973" velocity="2.175" />
        <axis xyz="0 0 1" />
        <dynamics damping="1.0" />
    </joint>
    <joint name="panda_2_joint4" type="revolute">
        <safety_controller k_position="100.0" k_velocity="40.0" soft_lower_limit="-3.0718" soft_upper_limit="-0.0698" />
        <origin rpy="1.5707963267948966 0 0" xyz="0.0825 0 0" />
        <parent link="panda_2_link3" />
        <child link="panda_2_link4" />
        <limit effort="87" lower="-3.0718" upper="-0.0698" velocity="2.175" />
        <axis xyz="0 0 1" />
        <dynamics damping="1.0" />
    </joint>
    <joint name="panda_2_joint5" type="revolute">
        <safety_controller k_position="100.0" k_velocity="40.0" soft_lower_limit="-2.8973" soft_upper_limit="2.8973" />
        <origin rpy="-1.5707963267948966 0 0" xyz="-0.0825 0.384 0" />
        <parent link="panda_2_link4" />
        <child link="panda_2_link5" />
        <limit effort="12" lower="-2.8973" upper="2.8973" velocity="2.61" />
        <axis xyz="0 0 1" />
        <dynamics damping="1.0" />
    </joint>
    <joint name="panda_2_joint6" type="revolute">
        <safety_controller k_position="100.0" k_velocity="40.0" soft_lower_limit="-0.0175" soft_upper_limit="3.7525" />
        <origin rpy="1.5707963267948966 0 0" xyz="0 0 0" />
        <parent link="panda_2_link5" />
        <child link="panda_2_link6" />
        <limit effort="12" lower="-0.0175" upper="3.7525" velocity="2.61" />
        <axis xyz="0 0 1" />
        <dynamics damping="1.0" />
    </joint>
    <joint name="panda_2_joint7" type="revolute">
        <safety_controller k_position="100.0" k_velocity="40.0" soft_lower_limit="-2.8973" soft_upper_limit="2.8973" />
        <origin rpy="1.5707963267948966 0 0" xyz="0.088 0 0" />
        <parent link="panda_2_link6" />
        <child link="panda_2_link7" />
        <limit effort="12" lower="-2.8973" upper="2.8973" velocity="2.61" />
        <axis xyz="0 0 1" />
        <dynamics damping="1.0" />
    </joint>
    <joint name="panda_2_joint8" type="fixed">
        <origin rpy="0 0 0" xyz="0 0 0.107" />
        <parent link="panda_2_link7" />
        <child link="panda_2_link8" />
        <axis xyz="0 0 0" />
        <dynamics damping="1.0" />
    </joint>
    <joint name="panda_2_hand_joint" type="fixed">
        <parent link="panda_2_link8" />
        <child link="panda_2_hand" />
        <origin rpy="0 0 -0.7853981633974483" xyz="0 0 0" />
    </joint>
    <link name="panda_2_hand">
        <visual>
            <geometry>
                <mesh filename="package://franka_description/meshes/visual/hand.dae" />
            </geometry>
        </visual>
        <collision>
            <origin rpy="0 1.5707963267948966 1.5707963267948966" xyz="0 0 0.04" />
            <geometry>
                <cylinder length="0.1" radius="0.07" />
            </geometry>
        </collision>
        <collision>
            <origin rpy="0 0 0" xyz="0 -0.05 0.04" />
            <geometry>
                <sphere radius="0.07" />
            </geometry>
        </collision>
        <collision>
            <origin rpy="0 0 0" xyz="0 0.05 0.04" />
            <geometry>
                <sphere radius="0.07" />
            </geometry>
        </collision>
        <collision>
            <origin rpy="0 1.5707963267948966 1.5707963267948966" xyz="0 0 0.1" />
            <geometry>
                <cylinder length="0.1" radius="0.05" />
            </geometry>
        </collision>
        <collision>
            <origin rpy="0 0 0" xyz="0 -0.05 0.1" />
            <geometry>
                <sphere radius="0.05" />
            </geometry>
        </collision>
        <collision>
            <origin rpy="0 0 0" xyz="0 0.05 0.1" />
            <geometry>
                <sphere radius="0.05" />
            </geometry>
        </collision>

<inertial>
            <mass value="0.1" />
            <inertia ixx="0.03" ixy="0.0" ixz="0.0" iyy="0.03" iyz="0.0" izz="0.03" />
        </inertial>

    </link>
    <link name="panda_2_leftfinger">
        <visual>
            <geometry>
                <mesh filename="package://franka_description/meshes/visual/finger.dae" />
            </geometry>
        </visual>
        <collision>
            <geometry>
                <sphere radius="0.05" />
            </geometry>
        </collision>

<inertial>
            <mass value="0.1" />
            <inertia ixx="0.03" ixy="0.0" ixz="0.0" iyy="0.03" iyz="0.0" izz="0.03" />
        </inertial>

    </link>
    <link name="panda_2_rightfinger">
        <visual>
            <origin rpy="0 0 3.141592653589793" xyz="0 0 0" />
            <geometry>
                <mesh filename="package://franka_description/meshes/visual/finger.dae" />
            </geometry>
        </visual>
        <collision>
            <geometry>
                <sphere radius="0.05" />
            </geometry>
        </collision>

<inertial>
            <mass value="0.1" />
            <inertia ixx="0.03" ixy="0.0" ixz="0.0" iyy="0.03" iyz="0.0" izz="0.03" />
        </inertial>

    </link>
    <joint name="panda_2_finger_joint1" type="prismatic">
        <parent link="panda_2_hand" />
        <child link="panda_2_leftfinger" />
        <origin rpy="0 0 0" xyz="0 0 0.0584" />
        <axis xyz="0 1 0" />
        <limit effort="150" lower="0.0" upper="0.04" velocity="0.2" />
    </joint>
    <joint name="panda_2_finger_joint2" type="prismatic">
        <parent link="panda_2_hand" />
        <child link="panda_2_rightfinger" />
        <origin rpy="0 0 0" xyz="0 0 0.0584" />
        <axis xyz="0 -1 0" />
        <limit effort="150" lower="0.0" upper="0.04" velocity="0.2" />
        <mimic joint="panda_2_finger_joint1" />
    </joint>
    <joint name="robot1_pedestal_joint" type="fixed">
        <origin rpy="0 0 0" xyz="-1.0 3.0 0.0" />
        <parent link="world_interface" />
        <child link="robot1_pedestal_link" />
    </joint>
    <link name="robot1_pedestal_link">
        <visual>
            <origin xyz="0 0 0.475" />
            <geometry>
                <box size="0.3 0.3 0.95" />
            </geometry>
            <material name="pedestal_color">
                <color rgba="0 0.1568627450980392 0.5254901960784314 1" />
            </material>
        </visual>
        <collision>
            <origin xyz="0 0 0.475" />
            <geometry>
                <box size="0.3 0.3 0.95" />
            </geometry>
        </collision>

<inertial>
            <mass value="500" />
            <origin rpy="0 0 0" xyz="0 0 0" />
            <inertia ixx="0.001" ixy="0" ixz="0" iyy="0.001" iyz="0" izz="0.001" />
        </inertial>

    </link>
    <gazebo reference="robot1_pedestal_link">
        <material>Gazebo/Blue</material>
    </gazebo>
    <joint name="robot2_pedestal_joint" type="fixed">
        <origin rpy="0 0 0" xyz="-1.0 -2.0 0.0" />
        <parent link="world_interface" />
        <child link="robot2_pedestal_link" />
    </joint>
    <link name="robot2_pedestal_link">
        <visual>
            <origin xyz="0 0 0.475" />
            <geometry>
                <box size="0.3 0.3 0.95" />
            </geometry>
            <material name="pedestal_color">
                <color rgba="0 0.1568627450980392 0.5254901960784314 1" />
            </material>
        </visual>
        <collision>
            <origin xyz="0 0 0.475" />
            <geometry>
                <box size="0.3 0.3 0.95" />
            </geometry>
        </collision>

<inertial>
            <mass value="500" />
            <origin rpy="0 0 0" xyz="0 0 0" />
            <inertia ixx="0.001" ixy="0" ixz="0" iyy="0.001" iyz="0" izz="0.001" />
        </inertial>

    </link>
    <gazebo reference="robot2_pedestal_link">
        <material>Gazebo/Blue</material>
    </gazebo>
    <!-- Links -->
    <link name="r1_festo_module">
        <visual>
            <geometry>
                <mesh filename="package://aau_lab_ros_models/meshes/festo_robot_module/festo_robot_module.dae" />
            </geometry>
        </visual>
        <collision>
            <geometry>
                <mesh filename="package://aau_lab_ros_models/meshes/festo_robot_module/festo_robot_module.dae" />
            </geometry>
        </collision>

<inertial>
            <inertia ixx="1.0" ixy="0" ixz="0" iyy="1.0" iyz="0" izz="1.0" />
            <mass value="100" />
        </inertial>

    </link>
    <joint name="r1_festo_module_to_world_interface" type="fixed">
        <origin rpy="0 0 0" xyz="-0.4 0.6 0.0" />
        <parent link="world_interface" />
        <child link="r1_festo_module" />
        <!-- <origin xyz="0 0 0" rpy="0 0 0" /> -->
    </joint>
    <!-- Links -->
    <link name="t1_festo_module">
        <visual>
            <geometry>
                <mesh filename="package://aau_lab_ros_models/meshes/festo_t_module/festo_t_module.dae" />
            </geometry>
        </visual>
        <collision>
            <geometry>
                <mesh filename="package://aau_lab_ros_models/meshes/festo_t_module/festo_t_module.dae" />
            </geometry>
        </collision>

<inertial>
            <inertia ixx="1.0" ixy="0" ixz="0" iyy="1.0" iyz="0" izz="1.0" />
            <mass value="100" />
        </inertial>

    </link>
    <joint name="t1_festo_module_to_world_interface" type="fixed">
        <origin rpy="0 0 0" xyz="-0.4 -0.6 0.0" />
        <parent link="world_interface" />
        <child link="t1_festo_module" />
        <!-- <origin xyz="0 0 0" rpy="0 0 0" /> -->
    </joint>
    <!-- Links -->
    <link name="s1_festo_module">
        <visual>
            <geometry>
                <mesh filename="package://aau_lab_ros_models/meshes/festo_straight_module/festo_straight_module.dae" />
            </geometry>
        </visual>
        <collision>
            <geometry>
                <mesh filename="package://aau_lab_ros_models/meshes/festo_straight_module/festo_straight_module.dae" />
            </geometry>
        </collision>

<inertial>
            <inertia ixx="1.0" ixy="0" ixz="0" iyy="1.0" iyz="0" izz="1.0" />
            <mass value="100" />
        </inertial>

    </link>
    <joint name="s1_festo_module_to_world_interface" type="fixed">
        <origin rpy="0 0 3.141592653589793" xyz="-0.4 -1.8 0.0" />
        <parent link="world_interface" />
        <child link="s1_festo_module" />
        <!-- <origin xyz="0 0 0" rpy="0 0 0" /> -->
    </joint>
    <!-- Links -->
    <link name="s2_festo_module">
        <visual>
            <geometry>
                <mesh filename="package://aau_lab_ros_models/meshes/festo_straight_module/festo_straight_module.dae" />
            </geometry>
        </visual>
        <collision>
            <geometry>
                <mesh filename="package://aau_lab_ros_models/meshes/festo_straight_module/festo_straight_module.dae" />
            </geometry>
        </collision>

<inertial>
            <inertia ixx="1.0" ixy="0" ixz="0" iyy="1.0" iyz="0" izz="1.0" />
            <mass value="100" />
        </inertial>

    </link>
    <joint name="s2_festo_module_to_world_interface" type="fixed">
        <origin rpy="0 0 3.141592653589793" xyz="-0.4 1.8 0.0" />
        <parent link="world_interface" />
        <child link="s2_festo_module" />
        <!-- <origin xyz="0 0 0" rpy="0 0 0" /> -->
    </joint>
    <!-- Links -->
    <link name="s3_festo_module">
        <visual>
            <geometry>
                <mesh filename="package://aau_lab_ros_models/meshes/festo_straight_module/festo_straight_module.dae" />
            </geometry>
        </visual>
        <collision>
            <geometry>
                <mesh filename="package://aau_lab_ros_models/meshes/festo_straight_module/festo_straight_module.dae" />
            </geometry>
        </collision>

<inertial>
            <inertia ixx="1.0" ixy="0" ixz="0" iyy="1.0" iyz="0" izz="1.0" />
            <mass value="100" />
        </inertial>

    </link>
    <joint name="s3_festo_module_to_world_interface" type="fixed">
        <origin rpy="0 0 0" xyz="-0.4 3.0 0.0" />
        <parent link="world_interface" />
        <child link="s3_festo_module" />
        <!-- <origin xyz="0 0 0" rpy="0 0 0" /> -->
    </joint>
    <!-- Links -->
    <link name="s4_festo_module">
        <visual>
            <geometry>
                <mesh filename="package://aau_lab_ros_models/meshes/festo_straight_module/festo_straight_module.dae" />
            </geometry>
        </visual>
        <collision>
            <geometry>
                <mesh filename="package://aau_lab_ros_models/meshes/festo_straight_module/festo_straight_module.dae" />
            </geometry>
        </collision>

<inertial>
            <inertia ixx="1.0" ixy="0" ixz="0" iyy="1.0" iyz="0" izz="1.0" />
            <mass value="100" />
        </inertial>

    </link>
    <joint name="s4_festo_module_to_world_interface" type="fixed">
        <origin rpy="0 0 1.5707963267948966" xyz="-1.4 -0.6 0.0" />
        <parent link="world_interface" />
        <child link="s4_festo_module" />
        <!-- <origin xyz="0 0 0" rpy="0 0 0" /> -->
    </joint>
    <!-- Links -->
    <link name="bp1_festo_module">
        <visual>
            <geometry>
                <mesh filename="package://aau_lab_ros_models/meshes/festo_bypass_module/festo_bypass_module.dae" />
            </geometry>
        </visual>
        <collision>
            <geometry>
                <mesh filename="package://aau_lab_ros_models/meshes/festo_bypass_module/festo_bypass_module.dae" />
            </geometry>
        </collision>

<inertial>
            <inertia ixx="1.0" ixy="0" ixz="0" iyy="1.0" iyz="0" izz="1.0" />
            <mass value="100" />
        </inertial>

    </link>
    <joint name="bp1_festo_module_to_world_interface" type="fixed">
        <origin rpy="0 0 1.5707963267948966" xyz="-2.6 -0.6 0.0" />
        <parent link="world_interface" />
        <child link="bp1_festo_module" />
        <!-- <origin xyz="0 0 0" rpy="0 0 0" /> -->
    </joint>
    <!-- ==================================================== -->
    <!-- Other Stuff -->
    <!-- ==================================================== -->
    <!-- Links -->
    <link name="ep1__eu_pallet">
        <visual>
            <geometry>
                <mesh filename="package://aau_lab_ros_models/meshes/eu_pallet/eu_pallet.dae" />
            </geometry>
        </visual>
        <collision>
            <geometry>
                <mesh filename="package://aau_lab_ros_models/meshes/eu_pallet/eu_pallet.dae" />
            </geometry>
        </collision>

<inertial>
            <inertia ixx="1.0" ixy="0" ixz="0" iyy="1.0" iyz="0" izz="1.0" />
            <mass value="25" />
        </inertial>

    </link>
    <joint name="ep1__to_world_interface" type="fixed">
        <origin rpy="0 0 0" xyz="1.0 0.0 0.0" />
        <parent link="world_interface" />
        <child link="ep1__eu_pallet" />
    </joint>
    <!-- Links -->
    <link name="n1__nurse">
        <visual>
            <geometry>
                <mesh filename="package://aau_lab_ros_models/meshes/nurse/nurse.dae" />
            </geometry>
        </visual>
        <collision>
            <geometry>
                <mesh filename="package://aau_lab_ros_models/meshes/nurse/nurse.dae" />
            </geometry>
        </collision>

<inertial>
            <inertia ixx="1.0" ixy="0" ixz="0" iyy="1.0" iyz="0" izz="1.0" />
            <mass value="25" />
        </inertial>

    </link>
    <joint name="n1__to_world_interface" type="fixed">
        <origin rpy="0 0 3.141592653589793" xyz="0.0 0.0 0.15" />
        <parent link="ep1__eu_pallet" />
        <child link="n1__nurse" />
    </joint>


    <transmission name="trans_panda_1_joint1">
        <type>transmission_interface/SimpleTransmission</type>
        <joint name="panda_1_joint1">
            <hardwareInterface>hardware_interface/EffortJointInterface</hardwareInterface>
        </joint>
        <actuator name="panda_1_joint1_motor">
            <hardwareInterface>hardware_interface/EffortJointInterface</hardwareInterface>
            <mechanicalReduction>1</mechanicalReduction>
        </actuator>
    </transmission>
    <transmission name="trans_panda_1_joint2">
        <type>transmission_interface/SimpleTransmission</type>
        <joint name="panda_1_joint2">
            <hardwareInterface>hardware_interface/EffortJointInterface</hardwareInterface>
        </joint>
        <actuator name="panda_1_joint2_motor">
            <hardwareInterface>hardware_interface/EffortJointInterface</hardwareInterface>
            <mechanicalReduction>1</mechanicalReduction>
        </actuator>
    </transmission>
    <transmission name="trans_panda_1_joint3">
        <type>transmission_interface/SimpleTransmission</type>
        <joint name="panda_1_joint3">
            <hardwareInterface>hardware_interface/EffortJointInterface</hardwareInterface>
        </joint>
        <actuator name="panda_1_joint3_motor">
            <hardwareInterface>hardware_interface/EffortJointInterface</hardwareInterface>
            <mechanicalReduction>1</mechanicalReduction>
        </actuator>
    </transmission>
    <transmission name="trans_panda_1_joint4">
        <type>transmission_interface/SimpleTransmission</type>
        <joint name="panda_1_joint4">
            <hardwareInterface>hardware_interface/EffortJointInterface</hardwareInterface>
        </joint>
        <actuator name="panda_1_joint4_motor">
            <hardwareInterface>hardware_interface/EffortJointInterface</hardwareInterface>
            <mechanicalReduction>1</mechanicalReduction>
        </actuator>
    </transmission>
    <transmission name="trans_panda_1_joint5">
        <type>transmission_interface/SimpleTransmission</type>
        <joint name="panda_1_joint5">
            <hardwareInterface>hardware_interface/EffortJointInterface</hardwareInterface>
        </joint>
        <actuator name="panda_1_joint5_motor">
            <hardwareInterface>hardware_interface/EffortJointInterface</hardwareInterface>
            <mechanicalReduction>1</mechanicalReduction>
        </actuator>
    </transmission>
    <transmission name="trans_panda_1_joint6">
        <type>transmission_interface/SimpleTransmission</type>
        <joint name="panda_1_joint6">
            <hardwareInterface>hardware_interface/EffortJointInterface</hardwareInterface>
        </joint>
        <actuator name="panda_1_joint6_motor">
            <hardwareInterface>hardware_interface/EffortJointInterface</hardwareInterface>
            <mechanicalReduction>1</mechanicalReduction>
        </actuator>
    </transmission>
    <transmission name="trans_panda_1_joint7">
        <type>transmission_interface/SimpleTransmission</type>
        <joint name="panda_1_joint7">
            <hardwareInterface>hardware_interface/EffortJointInterface</hardwareInterface>
        </joint>
        <actuator name="panda_1_joint7_motor">
            <hardwareInterface>hardware_interface/EffortJointInterface</hardwareInterface>
            <mechanicalReduction>1</mechanicalReduction>
        </actuator>
    </transmission>
    <transmission name="trans_panda_1_finger_joint1">
        <type>transmission_interface/SimpleTransmission</type>
        <joint name="panda_1_finger_joint1">
            <hardwareInterface>hardware_interface/EffortJointInterface</hardwareInterface>
        </joint>
        <actuator name="panda_1_finger_joint1_motor">
            <hardwareInterface>hardware_interface/EffortJointInterface</hardwareInterface>
            <mechanicalReduction>1</mechanicalReduction>
        </actuator>
    </transmission>
    <transmission name="trans_panda_1_finger_joint2">
        <type>transmission_interface/SimpleTransmission</type>
        <joint name="panda_1_finger_joint2">
            <hardwareInterface>hardware_interface/EffortJointInterface</hardwareInterface>
        </joint>
        <actuator name="panda_1_finger_joint2_motor">
            <hardwareInterface>hardware_interface/EffortJointInterface</hardwareInterface>
            <mechanicalReduction>1</mechanicalReduction>
        </actuator>
    </transmission>
    <transmission name="trans_panda_2_joint1">
        <type>transmission_interface/SimpleTransmission</type>
        <joint name="panda_2_joint1">
            <hardwareInterface>hardware_interface/EffortJointInterface</hardwareInterface>
        </joint>
        <actuator name="panda_2_joint1_motor">
            <hardwareInterface>hardware_interface/EffortJointInterface</hardwareInterface>
            <mechanicalReduction>1</mechanicalReduction>
        </actuator>
    </transmission>
    <transmission name="trans_panda_2_joint2">
        <type>transmission_interface/SimpleTransmission</type>
        <joint name="panda_2_joint2">
            <hardwareInterface>hardware_interface/EffortJointInterface</hardwareInterface>
        </joint>
        <actuator name="panda_2_joint2_motor">
            <hardwareInterface>hardware_interface/EffortJointInterface</hardwareInterface>
            <mechanicalReduction>1</mechanicalReduction>
        </actuator>
    </transmission>
    <transmission name="trans_panda_2_joint3">
        <type>transmission_interface/SimpleTransmission</type>
        <joint name="panda_2_joint3">
            <hardwareInterface>hardware_interface/EffortJointInterface</hardwareInterface>
        </joint>
        <actuator name="panda_2_joint3_motor">
            <hardwareInterface>hardware_interface/EffortJointInterface</hardwareInterface>
            <mechanicalReduction>1</mechanicalReduction>
        </actuator>
    </transmission>
    <transmission name="trans_panda_2_joint4">
        <type>transmission_interface/SimpleTransmission</type>
        <joint name="panda_2_joint4">
            <hardwareInterface>hardware_interface/EffortJointInterface</hardwareInterface>
        </joint>
        <actuator name="panda_2_joint4_motor">
            <hardwareInterface>hardware_interface/EffortJointInterface</hardwareInterface>
            <mechanicalReduction>1</mechanicalReduction>
        </actuator>
    </transmission>
    <transmission name="trans_panda_2_joint5">
        <type>transmission_interface/SimpleTransmission</type>
        <joint name="panda_2_joint5">
            <hardwareInterface>hardware_interface/EffortJointInterface</hardwareInterface>
        </joint>
        <actuator name="panda_2_joint5_motor">
            <hardwareInterface>hardware_interface/EffortJointInterface</hardwareInterface>
            <mechanicalReduction>1</mechanicalReduction>
        </actuator>
    </transmission>
    <transmission name="trans_panda_2_joint6">
        <type>transmission_interface/SimpleTransmission</type>
        <joint name="panda_2_joint6">
            <hardwareInterface>hardware_interface/EffortJointInterface</hardwareInterface>
        </joint>
        <actuator name="panda_2_joint6_motor">
            <hardwareInterface>hardware_interface/EffortJointInterface</hardwareInterface>
            <mechanicalReduction>1</mechanicalReduction>
        </actuator>
    </transmission>
    <transmission name="trans_panda_2_joint7">
        <type>transmission_interface/SimpleTransmission</type>
        <joint name="panda_2_joint7">
            <hardwareInterface>hardware_interface/EffortJointInterface</hardwareInterface>
        </joint>
        <actuator name="panda_2_joint7_motor">
            <hardwareInterface>hardware_interface/EffortJointInterface</hardwareInterface>
            <mechanicalReduction>1</mechanicalReduction>
        </actuator>
    </transmission>
    <transmission name="trans_panda_2_finger_joint1">
        <type>transmission_interface/SimpleTransmission</type>
        <joint name="panda_2_finger_joint1">
            <hardwareInterface>hardware_interface/EffortJointInterface</hardwareInterface>
        </joint>
        <actuator name="panda_2_finger_joint1_motor">
            <hardwareInterface>hardware_interface/EffortJointInterface</hardwareInterface>
            <mechanicalReduction>1</mechanicalReduction>
        </actuator>
    </transmission>
    <transmission name="trans_panda_2_finger_joint2">
        <type>transmission_interface/SimpleTransmission</type>
        <joint name="panda_2_finger_joint2">
            <hardwareInterface>hardware_interface/EffortJointInterface</hardwareInterface>
        </joint>
        <actuator name="panda_2_finger_joint2_motor">
            <hardwareInterface>hardware_interface/EffortJointInterface</hardwareInterface>
            <mechanicalReduction>1</mechanicalReduction>
        </actuator>
    </transmission>
    <gazebo>
        <plugin name="gazebo_ros_control" filename="libgazebo_ros_control.so">
            <robotNamespace>/</robotNamespace>
        </plugin>
    </gazebo>
</robot>
